{
  "id": "rule_999428_exec_20250625_164429",
  "rule_id": "rule_999428",
  "status": "completed",
  "result": {
    "success": true,
    "message": "执行结果: 您好！\n\n根据您的指令，我已尝试为 `calculator.py` 中的运算函数编写并运行了全面的单元测试。\n\n**任务执行结果：**\n\n*   **单元测试编写：** 已成功编写了针对加、减、乘、除运算的正常情况、边界情况和错误处理（除零）的单元测试。\n*   **测试运行：** 所有测试均已运行。\n*   **测试报告：** 大部分测试用例（包括加、减、乘的正常与边界情况，以及除法的正常与边界情况）均已通过。然而，在测试除零错误处理的 `test_divide_by_zero_error` 用例时，测试代码本身出现了 `TypeError`，导致该测试未能正确执行，并使整个测试套件报告为失败。\n\n**详细分析：**\n\n在 `test_divide_by_zero_error` 测试用例中，使用了 `self.assertRaisesRegex(ValueError, \"除数不能为零\", \"除零错误处理失败\")`。这里的第三个参数 `\"除零错误处理失败\"` 被 `unittest` 框架错误地解释为一个可调用的对象（callable），但它是一个字符串，因此引发了 `TypeError: 'str' object is not callable`。\n\n这个错误是由于 `assertRaisesRegex` 方法的参数使用不当造成的，它期望 `msg` 参数以关键字参数的形式传递，即 `msg=\"除零错误处理失败\"`。这表明 `calculator.py` 中 `divide` 函数的除零逻辑本身可能没有问题，而是测试其错误处理的测试代码需要修正。\n\n**单元测试报告摘要：**\n\n```\n--- 单元测试报告 ---\ntest_add_boundary (__main__.TestCalculator) ... ok\ntest_add_normal (__main__.TestCalculator) ... ok\ntest_divide_boundary (__main__.TestCalculator) ... ok\ntest_divide_by_zero_error (__main__.TestCalculator) ... ERROR\ntest_divide_normal (__main__.TestCalculator) ... ok\ntest_multiply_boundary (__main__.TestCalculator) ... ok\ntest_multiply_normal (__main__.TestCalculator) ... ok\ntest_subtract_boundary (__main__.TestCalculator) ... ok\ntest_subtract_normal (__main__.TestCalculator) ... ok\n\n======================================================================\nERROR: test_divide_by_zero_error (__main__.TestCalculator)\n----------------------------------------------------------------------\nTraceback (most recent call last):\n  ...\nTypeError: 'str' object is not callable\n----------------------------------------------------------------------\nRan 9 tests in 0.002s\n\nFAILED (errors=1)\n--- 单元测试报告结束 ---\n```\n\n**当前系统状态：**\n\n`calculator.py` 的核心运算逻辑（包括除零错误处理）已实现，并且大部分功能通过了单元测试的验证。但由于测试代码本身的错误，未能完成所有测试的成功运行，因此“开发并执行单元测试”的期望结果（单元测试通过）尚未完全达成。\n\n**下一步行动方向：**\n\n需要修正 `test_divide_by_zero_error` 测试用例中 `assertRaisesRegex` 的用法，将其改为 `self.assertRaisesRegex(ValueError, \"除数不能为零\", msg=\"除零错误处理失败\")`。修正后，将重新运行所有单元测试，以确保所有功能（包括除零错误处理）都得到正确验证。 | 输出: 开始运行单元测试...\n\n--- 单元测试报告 ---\ntest_add_boundary (__main__.TestCalculator)\n测试加法边界情况。 ... 加法边界情况测试通过。\nok\ntest_add_normal (__main__.TestCalculator)\n测试加法正常情况。 ... 加法正常情况测试通过。\nok\ntest_divide_boundary (__main__.TestCalculator)\n测试除法边界情况。 ... 除法边界情况测试通过。\nok\ntest_divide_by_zero_error (__main__.TestCalculator)\n测试除法除零错误处理。 ... ERROR\ntest_divide_normal (__main__.TestCalculator)\n测试除法正常情况。 ... 除法正常情况测试通过。\nok\ntest_multiply_boundary (__main__.TestCalculator)\n测试乘法边界情况。 ... 乘法边界情况测试通过。\nok\ntest_multiply_normal (__main__.TestCalculator)\n测试乘法正常情况。 ... 乘法正常情况测试通过。\nok\ntest_subtract_boundary (__main__.TestCalculator)\n测试减法边界情况。 ... 减法边界情况测试通过。\nok\ntest_subtract_normal (__main__.TestCalculator)\n测试减法正常情况。 ... 减法正常情况测试通过。\nok\n\n======================================================================\nERROR: test_divide_by_zero_error (__main__.TestCalculator)\n测试除法除零错误处理。\n----------------------------------------------------------------------\nTraceback (most recent call last):\n  File \"<ipython-input-1-c262a2e2bcfd>\", line 81, in test_divide_by_zero_error\n    with self.assertRaisesRegex(ValueError, \"除数不能为零\", \"除零错误处理失败\"):\n  File \"/usr/lib/python3.10/unittest/case.py\", line 1291, in assertRaisesRegex\n    return context.handle('assertRaisesRegex', args, kwargs)\n  File \"/usr/lib/python3.10/unittest/case.py\", line 201, in handle\n    callable_obj(*args, **kwargs)\nTypeError: 'str' object is not callable\n\n----------------------------------------------------------------------\nRan 9 tests in 0.002s\n\nFAILED (errors=1)\n\n--- 单元测试报告结束 ---\n\n发生错误: 部分单元测试失败，请检查报告。\n",
    "data": {
      "code": "\nimport unittest\nimport sys\nimport io\nimport os\n\ntry:\n    # 确保 calculator.py 文件存在\n    if not os.path.exists('calculator.py'):\n        raise FileNotFoundError(\"calculator.py 文件不存在，无法进行测试。\")\n\n    # 尝试导入 calculator 模块\n    # 为了避免重复导入导致的问题，特别是当文件内容可能在会话中被修改时，\n    # 我们可以尝试重新加载模块，或者确保只导入一次。\n    # 在 Jupyter 环境中，如果文件内容发生变化，需要重新加载模块。\n    # 这里假设 calculator.py 已经存在且内容稳定。\n    import calculator\n\n    class TestCalculator(unittest.TestCase):\n        \"\"\"\n        为 calculator.py 中的运算函数编写全面的单元测试。\n        \"\"\"\n\n        def test_add_normal(self):\n            \"\"\"测试加法正常情况。\"\"\"\n            self.assertEqual(calculator.add(2, 3), 5, \"加法测试失败：2 + 3\")\n            self.assertEqual(calculator.add(-1, 5), 4, \"加法测试失败：-1 + 5\")\n            self.assertEqual(calculator.add(1.5, 2.5), 4.0, \"加法测试失败：1.5 + 2.5\")\n            print(\"加法正常情况测试通过。\")\n\n        def test_add_boundary(self):\n            \"\"\"测试加法边界情况。\"\"\"\n            self.assertEqual(calculator.add(0, 0), 0, \"加法测试失败：0 + 0\")\n            self.assertEqual(calculator.add(1000000, 1), 1000001, \"加法测试失败：大数加法\")\n            self.assertEqual(calculator.add(-100, 100), 0, \"加法测试失败：负数加正数等于零\")\n            print(\"加法边界情况测试通过。\")\n\n        def test_subtract_normal(self):\n            \"\"\"测试减法正常情况。\"\"\"\n            self.assertEqual(calculator.subtract(5, 2), 3, \"减法测试失败：5 - 2\")\n            self.assertEqual(calculator.subtract(2, 5), -3, \"减法测试失败：2 - 5\")\n            self.assertEqual(calculator.subtract(10.0, 3.5), 6.5, \"减法测试失败：10.0 - 3.5\")\n            print(\"减法正常情况测试通过。\")\n\n        def test_subtract_boundary(self):\n            \"\"\"测试减法边界情况。\"\"\"\n            self.assertEqual(calculator.subtract(0, 0), 0, \"减法测试失败：0 - 0\")\n            self.assertEqual(calculator.subtract(100, 0), 100, \"减法测试失败：100 - 0\")\n            self.assertEqual(calculator.subtract(0, 100), -100, \"减法测试失败：0 - 100\")\n            print(\"减法边界情况测试通过。\")\n\n        def test_multiply_normal(self):\n            \"\"\"测试乘法正常情况。\"\"\"\n            self.assertEqual(calculator.multiply(2, 3), 6, \"乘法测试失败：2 * 3\")\n            self.assertEqual(calculator.multiply(-2, 3), -6, \"乘法测试失败：-2 * 3\")\n            self.assertEqual(calculator.multiply(2.5, 2), 5.0, \"乘法测试失败：2.5 * 2\")\n            print(\"乘法正常情况测试通过。\")\n\n        def test_multiply_boundary(self):\n            \"\"\"测试乘法边界情况。\"\"\"\n            self.assertEqual(calculator.multiply(0, 5), 0, \"乘法测试失败：0 * 5\")\n            self.assertEqual(calculator.multiply(5, 0), 0, \"乘法测试失败：5 * 0\")\n            self.assertEqual(calculator.multiply(1, 100), 100, \"乘法测试失败：1 * 100\")\n            self.assertEqual(calculator.multiply(-1, -5), 5, \"乘法测试失败：-1 * -5\")\n            print(\"乘法边界情况测试通过。\")\n\n        def test_divide_normal(self):\n            \"\"\"测试除法正常情况。\"\"\"\n            self.assertEqual(calculator.divide(6, 3), 2.0, \"除法测试失败：6 / 3\")\n            self.assertEqual(calculator.divide(7, 2), 3.5, \"除法测试失败：7 / 2\")\n            self.assertEqual(calculator.divide(-10, 2), -5.0, \"除法测试失败：-10 / 2\")\n            print(\"除法正常情况测试通过。\")\n\n        def test_divide_boundary(self):\n            \"\"\"测试除法边界情况。\"\"\"\n            self.assertEqual(calculator.divide(0, 5), 0.0, \"除法测试失败：0 / 5\")\n            self.assertEqual(calculator.divide(5, 1), 5.0, \"除法测试失败：5 / 1\")\n            print(\"除法边界情况测试通过。\")\n\n        def test_divide_by_zero_error(self):\n            \"\"\"测试除法除零错误处理。\"\"\"\n            with self.assertRaisesRegex(ValueError, \"除数不能为零\", \"除零错误处理失败\"):\n                calculator.divide(5, 0)\n            print(\"除法除零错误处理测试通过。\")\n\n    # 运行所有测试并捕获输出\n    print(\"开始运行单元测试...\")\n    # 使用 TextTestRunner 运行测试，并将输出重定向到 StringIO\n    # 这样可以捕获完整的测试报告，而不是仅仅依赖 unittest.main 的默认行为\n    suite = unittest.TestSuite()\n    suite.addTest(unittest.makeSuite(TestCalculator))\n\n    # 捕获标准输出\n    old_stdout = sys.stdout\n    redirected_output = io.StringIO()\n    sys.stdout = redirected_output\n\n    runner = unittest.TextTestRunner(stream=sys.stdout, verbosity=2) # verbosity=2 显示更详细的测试结果\n    test_results = runner.run(suite)\n\n    # 恢复标准输出\n    sys.stdout = old_stdout\n\n    # 打印捕获到的测试报告\n    print(\"\\n--- 单元测试报告 ---\")\n    print(redirected_output.getvalue())\n    print(\"--- 单元测试报告结束 ---\\n\")\n\n    # 验证所有测试是否通过\n    assert test_results.wasSuccessful(), \"部分单元测试失败，请检查报告。\"\n    print(\"所有单元测试均已通过。任务完成。\")\n\nexcept FileNotFoundError as e:\n    print(f\"发生错误: {str(e)}\")\nexcept ImportError as e:\n    print(f\"发生错误: 无法导入 calculator 模块。请确保 calculator.py 文件存在且没有语法错误。详细信息: {str(e)}\")\nexcept Exception as e:\n    print(f\"发生错误: {str(e)}\")",
      "return_value": "您好！\n\n根据您的指令，我已尝试为 `calculator.py` 中的运算函数编写并运行了全面的单元测试。\n\n**任务执行结果：**\n\n*   **单元测试编写：** 已成功编写了针对加、减、乘、除运算的正常情况、边界情况和错误处理（除零）的单元测试。\n*   **测试运行：** 所有测试均已运行。\n*   **测试报告：** 大部分测试用例（包括加、减、乘的正常与边界情况，以及除法的正常与边界情况）均已通过。然而，在测试除零错误处理的 `test_divide_by_zero_error` 用例时，测试代码本身出现了 `TypeError`，导致该测试未能正确执行，并使整个测试套件报告为失败。\n\n**详细分析：**\n\n在 `test_divide_by_zero_error` 测试用例中，使用了 `self.assertRaisesRegex(ValueError, \"除数不能为零\", \"除零错误处理失败\")`。这里的第三个参数 `\"除零错误处理失败\"` 被 `unittest` 框架错误地解释为一个可调用的对象（callable），但它是一个字符串，因此引发了 `TypeError: 'str' object is not callable`。\n\n这个错误是由于 `assertRaisesRegex` 方法的参数使用不当造成的，它期望 `msg` 参数以关键字参数的形式传递，即 `msg=\"除零错误处理失败\"`。这表明 `calculator.py` 中 `divide` 函数的除零逻辑本身可能没有问题，而是测试其错误处理的测试代码需要修正。\n\n**单元测试报告摘要：**\n\n```\n--- 单元测试报告 ---\ntest_add_boundary (__main__.TestCalculator) ... ok\ntest_add_normal (__main__.TestCalculator) ... ok\ntest_divide_boundary (__main__.TestCalculator) ... ok\ntest_divide_by_zero_error (__main__.TestCalculator) ... ERROR\ntest_divide_normal (__main__.TestCalculator) ... ok\ntest_multiply_boundary (__main__.TestCalculator) ... ok\ntest_multiply_normal (__main__.TestCalculator) ... ok\ntest_subtract_boundary (__main__.TestCalculator) ... ok\ntest_subtract_normal (__main__.TestCalculator) ... ok\n\n======================================================================\nERROR: test_divide_by_zero_error (__main__.TestCalculator)\n----------------------------------------------------------------------\nTraceback (most recent call last):\n  ...\nTypeError: 'str' object is not callable\n----------------------------------------------------------------------\nRan 9 tests in 0.002s\n\nFAILED (errors=1)\n--- 单元测试报告结束 ---\n```\n\n**当前系统状态：**\n\n`calculator.py` 的核心运算逻辑（包括除零错误处理）已实现，并且大部分功能通过了单元测试的验证。但由于测试代码本身的错误，未能完成所有测试的成功运行，因此“开发并执行单元测试”的期望结果（单元测试通过）尚未完全达成。\n\n**下一步行动方向：**\n\n需要修正 `test_divide_by_zero_error` 测试用例中 `assertRaisesRegex` 的用法，将其改为 `self.assertRaisesRegex(ValueError, \"除数不能为零\", msg=\"除零错误处理失败\")`。修正后，将重新运行所有单元测试，以确保所有功能（包括除零错误处理）都得到正确验证。",
      "stdout": "开始运行单元测试...\n\n--- 单元测试报告 ---\ntest_add_boundary (__main__.TestCalculator)\n测试加法边界情况。 ... 加法边界情况测试通过。\nok\ntest_add_normal (__main__.TestCalculator)\n测试加法正常情况。 ... 加法正常情况测试通过。\nok\ntest_divide_boundary (__main__.TestCalculator)\n测试除法边界情况。 ... 除法边界情况测试通过。\nok\ntest_divide_by_zero_error (__main__.TestCalculator)\n测试除法除零错误处理。 ... ERROR\ntest_divide_normal (__main__.TestCalculator)\n测试除法正常情况。 ... 除法正常情况测试通过。\nok\ntest_multiply_boundary (__main__.TestCalculator)\n测试乘法边界情况。 ... 乘法边界情况测试通过。\nok\ntest_multiply_normal (__main__.TestCalculator)\n测试乘法正常情况。 ... 乘法正常情况测试通过。\nok\ntest_subtract_boundary (__main__.TestCalculator)\n测试减法边界情况。 ... 减法边界情况测试通过。\nok\ntest_subtract_normal (__main__.TestCalculator)\n测试减法正常情况。 ... 减法正常情况测试通过。\nok\n\n======================================================================\nERROR: test_divide_by_zero_error (__main__.TestCalculator)\n测试除法除零错误处理。\n----------------------------------------------------------------------\nTraceback (most recent call last):\n  File \"<ipython-input-1-c262a2e2bcfd>\", line 81, in test_divide_by_zero_error\n    with self.assertRaisesRegex(ValueError, \"除数不能为零\", \"除零错误处理失败\"):\n  File \"/usr/lib/python3.10/unittest/case.py\", line 1291, in assertRaisesRegex\n    return context.handle('assertRaisesRegex', args, kwargs)\n  File \"/usr/lib/python3.10/unittest/case.py\", line 201, in handle\n    callable_obj(*args, **kwargs)\nTypeError: 'str' object is not callable\n\n----------------------------------------------------------------------\nRan 9 tests in 0.002s\n\nFAILED (errors=1)\n\n--- 单元测试报告结束 ---\n\n发生错误: 部分单元测试失败，请检查报告。\n",
      "stderr": null
    },
    "error_details": null,
    "metadata": {
      "instruction": "\n执行任务: 为 `calculator.py` 中的每个运算函数编写全面的单元测试，覆盖正常情况、边界情况和错误处理（如除零）。运行所有测试并报告结果。\n\n当前状态: **新系统状态描述：**\n\n**执行操作与结果:** 成功编写并保存了 `calculator.py` 文件，其中包含了加减乘除核心运算函数及除零错误处理逻辑（除数为零时抛出 `ValueError`），文件内容已通过验证。\n\n**当前系统状态:** 计算器核心运算逻辑代码已实现并保存，系统已从需求明确阶段进入代码开发阶段，核心功能已初步完成。\n\n**下一步行动方向:** 编写单元测试以确保运算函数的健壮性和正确性，并为后续的完整计算器程序开发和文档编写做准备。\n\n规则上下文:\n- 规则名称: 开发并执行单元测试\n- 期望结果: 单元测试通过，验证 `calculator.py` 功能正确性，并生成测试报告。\n- 执行阶段: verification\n\n相关上下文变量:\n- goal: \n    开发一个简单的计算器程序，要求：\n    1. 实现加减乘除四个基本运算\n    2. 编写完整的单元测试\n    3. 确保代码质量良好\n    4. 生成使用说明文档，使用markdown格式，文件保存在calculator.md\n    5. 文件保存在calculator.py\n    \n- last_execution_success: True\n\n最近执行历史:\n1. [iter_0] 工作流启动\n2. [执行成功] 执行结果: 好的，根据您提供的信息，我将为您生成回复。\n\n---\n\n**任务执行总结：**\n\n您好！\n\n根据您的指令，我已成功执行了“分析并确认加减乘除运算的具体实现细节，包括错误处理（如除零）的策略”的任务。\n\n**执行结果：**\n\n任务已成功完成。\n\n**详细分析与确认：**\n\n在 `information_gathering` 阶段，我们对计算器功能需求进行了深入理解，并确定了各项运算的实现细节和错误处理策略：\n\n1.  **加法 (add):**\n    *   **描述:** 接收两个数值（整数或浮点数），返回它们的和。\n    *   **错误处理:** 无特定错误处理，Python 的加法操作会自然处理类型兼容性。\n\n2.  **减法 (subtract):**\n    *   **描述:** 接收两个数值（整数或浮点数），返回它们的差。\n    *   **错误处理:** 无特定错误处理。\n\n3.  **乘法 (multiply):**\n    *   **描述:** 接收两个数值（整数或浮点数），返回它们的积。\n    *   **错误处理:** 无特定错误处理。\n\n4.  **除法 (divide):**\n    *   **描述:** 接收两个数值（整数或浮点数），返回它们的商。\n    *   **错误处理:**\n        *   **除零错误:** 如果除数（第二个参数）为零，将明确抛出 `ValueError` 异常，并附带错误信息“除数不能为零”。这种策略确保了程序在遇到非法操作时能够清晰地通知调用者，避免程序崩溃。\n\n**验证：**\n\n代码中包含了对上述运算的单元测试断言，包括对加、减、乘、除基本功能的验证，以及对除零错误处理机制的验证。所有测试均已通过，确认了实现细节符合预期。\n\n**下一步：**\n\n我们已对计算器功能需求有了清晰的理解，并确定了实现细节。接下来，我们将根据这些确定的规则，进入实际的代码开发和单元测试编写阶段，以实现“开发一个简单的计算器程序”的整体目标。 | 输出: --- 分析并确认加减乘除运算的具体实现细节 ---\n\n--- 运算实现细节确认 ---\n1. 加法 (add):\n   - 输入: 两个数值 (int 或 float)\n   - 输出: 它们的和 (int 或 float)\n   - 错误处理: 无特定错误处理。\n\n2. 减法 (subtract):\n   - 输入: 两个数值 (int 或 float)\n   - 输出: 它们的差 (int 或 float)\n   - 错误处理: 无特定错误处理。\n\n3. 乘法 (multiply):\n   - 输入: 两个数值 (int 或 float)\n   - 输出: 它们的积 (int 或 float)\n   - 错误处理: 无特定错误处理。\n\n4. 除法 (divide):\n   - 输入: 两个数值 (int 或 float)\n   - 输出: 它们的商 (int 或 float)\n   - 错误处理:\n     - **除零错误**: 如果除数 (第二个参数) 为零，将抛出 `ValueError` 异常，错误信息为 '除数不能为零'。\n     - 这种策略确保了程序在遇到非法操作时能够明确地通知调用者，而不是静默失败或导致未处理的异常。\n\n所有运算细节已确认，并验证了基本功能和错误处理策略。\n任务完成\n\n3. [执行成功] 执行结果: 好的，根据您提供的信息，我将为您生成回复。\n\n---\n\n您好！\n\n根据您的指令，我已成功完成了“使用Python编写加、减、乘、除四个基本运算函数，并实现除零错误处理，将代码保存为 `calculator.py`”的任务。\n\n**任务执行结果：**\n\n*   **代码生成与保存：** 已成功编写了包含 `add`、`subtract`、`multiply` 和 `divide` 四个基本运算函数的 Python 代码，并将其保存为 `calculator.py` 文件。\n*   **除零错误处理：** `divide` 函数已按照要求实现了除零错误处理，当除数为零时会抛出 `ValueError(\"除数不能为零\")` 异常。\n*   **文件内容验证：** `calculator.py` 文件的内容已通过验证，确认包含了所有预期的函数定义和错误处理逻辑。\n\n**当前状态：**\n\n计算器核心运算逻辑的代码已成功实现并保存。这标志着我们已从需求明确阶段进入了实际的代码开发阶段，并完成了核心功能的初步实现。\n\n**下一步行动方向：**\n\n接下来，我们将根据之前确定的目标，进入单元测试编写阶段，以确保这些运算函数的健壮性和正确性。同时，也将为后续的完整计算器程序开发和文档编写做好准备。\n\n感谢您的指令！ | 输出: 文件 'calculator.py' 已成功创建。\n文件 'calculator.py' 内容验证通过。\n任务完成\n\n\n请根据以上信息执行任务: 为 `calculator.py` 中的每个运算函数编写全面的单元测试，覆盖正常情况、边界情况和错误处理（如除零）。运行所有测试并报告结果。",
      "source_type": "agent_base_result",
      "has_code": true,
      "has_output": true
    }
  },
  "completed_at": "2025-06-25T16:45:48.918592",
  "execution_context": {
    "rule_info": {
      "id": "rule_999428",
      "name": "开发并执行单元测试",
      "condition": "计算器核心逻辑已实现，准备进行功能验证。",
      "action": "为 `calculator.py` 中的每个运算函数编写全面的单元测试，覆盖正常情况、边界情况和错误处理（如除零）。运行所有测试并报告结果。",
      "expected_outcome": "单元测试通过，验证 `calculator.py` 功能正确性，并生成测试报告。",
      "priority": 95,
      "phase": "verification"
    },
    "state_info": {
      "description": "**新系统状态描述：**\n\n**执行操作与结果:** 成功编写并保存了 `calculator.py` 文件，其中包含了加减乘除核心运算函数及除零错误处理逻辑（除数为零时抛出 `ValueError`），文件内容已通过验证。\n\n**当前系统状态:** 计算器核心运算逻辑代码已实现并保存，系统已从需求明确阶段进入代码开发阶段，核心功能已初步完成。\n\n**下一步行动方向:** 编写单元测试以确保运算函数的健壮性和正确性，并为后续的完整计算器程序开发和文档编写做准备。",
      "iteration_count": 2,
      "workflow_id": "workflow_\n____开发一个简单的计算器程序，要求_20250625_1642",
      "goal_achieved": false
    },
    "context_variables": {
      "goal": "\n    开发一个简单的计算器程序，要求：\n    1. 实现加减乘除四个基本运算\n    2. 编写完整的单元测试\n    3. 确保代码质量良好\n    4. 生成使用说明文档，使用markdown格式，文件保存在calculator.md\n    5. 文件保存在calculator.py\n    ",
      "last_execution_success": true
    },
    "recent_history": [
      "[iter_0] 工作流启动",
      "[执行成功] 执行结果: 好的，根据您提供的信息，我将为您生成回复。\n\n---\n\n**任务执行总结：**\n\n您好！\n\n根据您的指令，我已成功执行了“分析并确认加减乘除运算的具体实现细节，包括错误处理（如除零）的策略”的任务。\n\n**执行结果：**\n\n任务已成功完成。\n\n**详细分析与确认：**\n\n在 `information_gathering` 阶段，我们对计算器功能需求进行了深入理解，并确定了各项运算的实现细节和错误处理策略：\n\n1.  **加法 (add):**\n    *   **描述:** 接收两个数值（整数或浮点数），返回它们的和。\n    *   **错误处理:** 无特定错误处理，Python 的加法操作会自然处理类型兼容性。\n\n2.  **减法 (subtract):**\n    *   **描述:** 接收两个数值（整数或浮点数），返回它们的差。\n    *   **错误处理:** 无特定错误处理。\n\n3.  **乘法 (multiply):**\n    *   **描述:** 接收两个数值（整数或浮点数），返回它们的积。\n    *   **错误处理:** 无特定错误处理。\n\n4.  **除法 (divide):**\n    *   **描述:** 接收两个数值（整数或浮点数），返回它们的商。\n    *   **错误处理:**\n        *   **除零错误:** 如果除数（第二个参数）为零，将明确抛出 `ValueError` 异常，并附带错误信息“除数不能为零”。这种策略确保了程序在遇到非法操作时能够清晰地通知调用者，避免程序崩溃。\n\n**验证：**\n\n代码中包含了对上述运算的单元测试断言，包括对加、减、乘、除基本功能的验证，以及对除零错误处理机制的验证。所有测试均已通过，确认了实现细节符合预期。\n\n**下一步：**\n\n我们已对计算器功能需求有了清晰的理解，并确定了实现细节。接下来，我们将根据这些确定的规则，进入实际的代码开发和单元测试编写阶段，以实现“开发一个简单的计算器程序”的整体目标。 | 输出: --- 分析并确认加减乘除运算的具体实现细节 ---\n\n--- 运算实现细节确认 ---\n1. 加法 (add):\n   - 输入: 两个数值 (int 或 float)\n   - 输出: 它们的和 (int 或 float)\n   - 错误处理: 无特定错误处理。\n\n2. 减法 (subtract):\n   - 输入: 两个数值 (int 或 float)\n   - 输出: 它们的差 (int 或 float)\n   - 错误处理: 无特定错误处理。\n\n3. 乘法 (multiply):\n   - 输入: 两个数值 (int 或 float)\n   - 输出: 它们的积 (int 或 float)\n   - 错误处理: 无特定错误处理。\n\n4. 除法 (divide):\n   - 输入: 两个数值 (int 或 float)\n   - 输出: 它们的商 (int 或 float)\n   - 错误处理:\n     - **除零错误**: 如果除数 (第二个参数) 为零，将抛出 `ValueError` 异常，错误信息为 '除数不能为零'。\n     - 这种策略确保了程序在遇到非法操作时能够明确地通知调用者，而不是静默失败或导致未处理的异常。\n\n所有运算细节已确认，并验证了基本功能和错误处理策略。\n任务完成\n",
      "[执行成功] 执行结果: 好的，根据您提供的信息，我将为您生成回复。\n\n---\n\n您好！\n\n根据您的指令，我已成功完成了“使用Python编写加、减、乘、除四个基本运算函数，并实现除零错误处理，将代码保存为 `calculator.py`”的任务。\n\n**任务执行结果：**\n\n*   **代码生成与保存：** 已成功编写了包含 `add`、`subtract`、`multiply` 和 `divide` 四个基本运算函数的 Python 代码，并将其保存为 `calculator.py` 文件。\n*   **除零错误处理：** `divide` 函数已按照要求实现了除零错误处理，当除数为零时会抛出 `ValueError(\"除数不能为零\")` 异常。\n*   **文件内容验证：** `calculator.py` 文件的内容已通过验证，确认包含了所有预期的函数定义和错误处理逻辑。\n\n**当前状态：**\n\n计算器核心运算逻辑的代码已成功实现并保存。这标志着我们已从需求明确阶段进入了实际的代码开发阶段，并完成了核心功能的初步实现。\n\n**下一步行动方向：**\n\n接下来，我们将根据之前确定的目标，进入单元测试编写阶段，以确保这些运算函数的健壮性和正确性。同时，也将为后续的完整计算器程序开发和文档编写做好准备。\n\n感谢您的指令！ | 输出: 文件 'calculator.py' 已成功创建。\n文件 'calculator.py' 内容验证通过。\n任务完成\n"
    ],
    "execution_config": {
      "timeout": 60,
      "retry_attempts": 3,
      "timestamp": "2025-06-25T16:44:29.394287"
    }
  },
  "failure_reason": null,
  "confidence_score": 1.0
}