{
  "id": "rule_950765_exec_20250625_170354",
  "rule_id": "rule_950765",
  "status": "running",
  "result": null,
  "completed_at": null,
  "execution_context": {
    "rule_info": {
      "id": "rule_950765",
      "name": "生成使用说明文档",
      "condition": "计算器核心逻辑已初步实现。",
      "action": "为 `calculator.py` 编写使用说明文档，采用Markdown格式，并保存为 `calculator.md`。",
      "expected_outcome": "生成 `calculator.md` 文件，包含程序的使用说明。",
      "priority": 75,
      "phase": "problem_solving"
    },
    "state_info": {
      "description": "**新系统状态描述：**\n\n**执行操作与结果:**\n成功修正了 `calculator.py` 中 `test_divide_by_zero_error` 单元测试的参数使用问题，并重新运行了所有单元测试。所有9个测试用例均已通过，确认了 `calculator.py` 核心运算逻辑的正确性。\n\n**当前系统状态:**\n`calculator.py` 的核心逻辑已实现并经过全面单元测试验证，功能已完全正确。`calculator.md` 使用说明文档的生成任务仍待完成，目前内容不完整。\n\n**下一步行动方向:**\n重新生成并完善 `calculator.md` 使用说明文档，确保其包含完整的代码示例、使用方法和错误处理说明。",
      "iteration_count": 7,
      "workflow_id": "workflow_\n____开发一个简单的计算器程序，要求_20250625_1642",
      "goal_achieved": false
    },
    "context_variables": {
      "goal": "\n    开发一个简单的计算器程序，要求：\n    1. 实现加减乘除四个基本运算\n    2. 编写完整的单元测试\n    3. 确保代码质量良好\n    4. 生成使用说明文档，使用markdown格式，文件保存在calculator.md\n    5. 文件保存在calculator.py\n    ",
      "last_execution_success": true
    },
    "recent_history": [
      "[执行成功] 执行结果: 您好！\n\n根据您的指令，我已尝试为 `calculator.py` 中的运算函数编写并运行了全面的单元测试。\n\n**任务执行结果：**\n\n*   **单元测试编写：** 已成功编写了针对加、减、乘、除运算的正常情况、边界情况和错误处理（除零）的单元测试。\n*   **测试运行：** 所有测试均已运行。\n*   **测试报告：** 大部分测试用例（包括加、减、乘的正常与边界情况，以及除法的正常与边界情况）均已通过。然而，在测试除零错误处理的 `test_divide_by_zero_error` 用例时，测试代码本身出现了 `TypeError`，导致该测试未能正确执行，并使整个测试套件报告为失败。\n\n**详细分析：**\n\n在 `test_divide_by_zero_error` 测试用例中，使用了 `self.assertRaisesRegex(ValueError, \"除数不能为零\", \"除零错误处理失败\")`。这里的第三个参数 `\"除零错误处理失败\"` 被 `unittest` 框架错误地解释为一个可调用的对象（callable），但它是一个字符串，因此引发了 `TypeError: 'str' object is not callable`。\n\n这个错误是由于 `assertRaisesRegex` 方法的参数使用不当造成的，它期望 `msg` 参数以关键字参数的形式传递，即 `msg=\"除零错误处理失败\"`。这表明 `calculator.py` 中 `divide` 函数的除零逻辑本身可能没有问题，而是测试其错误处理的测试代码需要修正。\n\n**单元测试报告摘要：**\n\n```\n--- 单元测试报告 ---\ntest_add_boundary (__main__.TestCalculator) ... ok\ntest_add_normal (__main__.TestCalculator) ... ok\ntest_divide_boundary (__main__.TestCalculator) ... ok\ntest_divide_by_zero_error (__main__.TestCalculator) ... ERROR\ntest_divide_normal (__main__.TestCalculator) ... ok\ntest_multiply_boundary (__main__.TestCalculator) ... ok\ntest_multiply_normal (__main__.TestCalculator) ... ok\ntest_subtract_boundary (__main__.TestCalculator) ... ok\ntest_subtract_normal (__main__.TestCalculator) ... ok\n\n======================================================================\nERROR: test_divide_by_zero_error (__main__.TestCalculator)\n----------------------------------------------------------------------\nTraceback (most recent call last):\n  ...\nTypeError: 'str' object is not callable\n----------------------------------------------------------------------\nRan 9 tests in 0.002s\n\nFAILED (errors=1)\n--- 单元测试报告结束 ---\n```\n\n**当前系统状态：**\n\n`calculator.py` 的核心运算逻辑（包括除零错误处理）已实现，并且大部分功能通过了单元测试的验证。但由于测试代码本身的错误，未能完成所有测试的成功运行，因此“开发并执行单元测试”的期望结果（单元测试通过）尚未完全达成。\n\n**下一步行动方向：**\n\n需要修正 `test_divide_by_zero_error` 测试用例中 `assertRaisesRegex` 的用法，将其改为 `self.assertRaisesRegex(ValueError, \"除数不能为零\", msg=\"除零错误处理失败\")`。修正后，将重新运行所有单元测试，以确保所有功能（包括除零错误处理）都得到正确验证。 | 输出: 开始运行单元测试...\n\n--- 单元测试报告 ---\ntest_add_boundary (__main__.TestCalculator)\n测试加法边界情况。 ... 加法边界情况测试通过。\nok\ntest_add_normal (__main__.TestCalculator)\n测试加法正常情况。 ... 加法正常情况测试通过。\nok\ntest_divide_boundary (__main__.TestCalculator)\n测试除法边界情况。 ... 除法边界情况测试通过。\nok\ntest_divide_by_zero_error (__main__.TestCalculator)\n测试除法除零错误处理。 ... ERROR\ntest_divide_normal (__main__.TestCalculator)\n测试除法正常情况。 ... 除法正常情况测试通过。\nok\ntest_multiply_boundary (__main__.TestCalculator)\n测试乘法边界情况。 ... 乘法边界情况测试通过。\nok\ntest_multiply_normal (__main__.TestCalculator)\n测试乘法正常情况。 ... 乘法正常情况测试通过。\nok\ntest_subtract_boundary (__main__.TestCalculator)\n测试减法边界情况。 ... 减法边界情况测试通过。\nok\ntest_subtract_normal (__main__.TestCalculator)\n测试减法正常情况。 ... 减法正常情况测试通过。\nok\n\n======================================================================\nERROR: test_divide_by_zero_error (__main__.TestCalculator)\n测试除法除零错误处理。\n----------------------------------------------------------------------\nTraceback (most recent call last):\n  File \"<ipython-input-1-c262a2e2bcfd>\", line 81, in test_divide_by_zero_error\n    with self.assertRaisesRegex(ValueError, \"除数不能为零\", \"除零错误处理失败\"):\n  File \"/usr/lib/python3.10/unittest/case.py\", line 1291, in assertRaisesRegex\n    return context.handle('assertRaisesRegex', args, kwargs)\n  File \"/usr/lib/python3.10/unittest/case.py\", line 201, in handle\n    callable_obj(*args, **kwargs)\nTypeError: 'str' object is not callable\n\n----------------------------------------------------------------------\nRan 9 tests in 0.002s\n\nFAILED (errors=1)\n\n--- 单元测试报告结束 ---\n\n发生错误: 部分单元测试失败，请检查报告。\n",
      "[执行失败] 执行结果: 您好！\n\n根据您的指令，我尝试为 `calculator.py` 编写使用说明文档 `calculator.md`，但此任务未能成功完成。\n\n**任务执行结果与分析：**\n\n尽管我尝试生成了 `calculator.md` 文件，但根据系统反馈，本次操作被标记为失败，并提示“超过最大尝试次数，编程失败”。这可能意味着生成的文档内容不符合预期，或者在后续的验证步骤中未能通过。\n\n初步检查发现，我生成的 Markdown 内容在代码示例部分存在缺失，例如导入模块、调用函数的具体代码块以及 `if __name__ == '__main__':` 示例的输出部分并未完整包含在文档字符串中。这导致了文档的实用性不足，未能达到生成完整使用说明文档的期望。\n\n**当前系统状态：**\n\n`calculator.py` 的核心运算逻辑（包括除零错误处理）已实现，并且大部分功能通过了单元测试的初步验证。然而，单元测试中 `test_divide_by_zero_error` 用例因测试代码本身的参数使用不当而失败，导致整个测试套件报告为失败。同时，生成使用说明文档的任务也未能成功完成，文档内容不完整。\n\n**下一步行动方向：**\n\n为了确保项目的完整性和质量，我们需要执行以下步骤：\n\n1.  **修正单元测试：** 首先，修正 `test_divide_by_zero_error` 测试用例中 `assertRaisesRegex` 的用法，将其 `msg` 参数改为关键字参数形式，然后重新运行所有单元测试，以确保所有功能（特别是除零错误处理）都得到正确验证。\n2.  **完善使用说明文档：** 在确认 `calculator.py` 功能完全正确并通过所有测试后，我将重新编写并生成 `calculator.md` 文件，确保其中包含完整的代码示例、使用方法和错误处理说明，使其成为一份高质量的使用说明文档。\n\n感谢您的指令！ | 输出: 超过最大尝试次数，编程失败。",
      "[执行失败] 执行结果: 您好！\n\n根据您的指令，我再次尝试为 `calculator.py` 编写使用说明文档 `calculator.md`。\n\n**任务执行结果与分析：**\n\n遗憾的是，本次任务未能成功完成。系统反馈显示“超过最大尝试次数，编程失败”，这表明生成的文档未能通过完整性或质量检查。\n\n经过分析，我发现本次尝试生成的 `calculator.md` 内容仍然不完整，尤其是在**代码示例**部分。文档中缺少了关键的导入模块代码块、各个运算函数的具体调用示例代码，以及 `if __name__ == '__main__':` 块的完整代码和其对应的输出示例。这导致文档的实用性不足，未能达到生成高质量使用说明文档的期望。\n\n**当前系统状态：**\n\n*   `calculator.py` 的核心运算逻辑已实现，并且大部分功能通过了单元测试的初步验证。\n*   然而，单元测试中 `test_divide_by_zero_error` 用例仍因测试代码自身错误（`assertRaisesRegex` 参数使用不当）而失败，导致整个测试套件报告失败。\n*   `calculator.md` 文档生成失败且内容不完整。\n\n**下一步行动方向：**\n\n为了确保项目的完整性和质量，我们将按照以下步骤继续：\n\n1.  **修正单元测试：** 首要任务是修正 `test_divide_by_zero_error` 测试用例中 `assertRaisesRegex` 的用法，然后重新运行所有单元测试，以确保 `calculator.py` 的所有功能（特别是除零错误处理）都得到正确验证。\n2.  **完善使用说明文档：** 在确认 `calculator.py` 功能完全正确并通过所有测试后，我将重新编写并生成 `calculator.md` 文件，确保其中包含完整的代码示例、使用方法和错误处理说明，使其成为一份高质量且实用的使用说明文档。\n\n感谢您的指令！ | 输出: 超过最大尝试次数，编程失败。",
      "[执行失败] 执行结果: 您好！\n\n根据您的指令，我再次尝试为 `calculator.py` 编写使用说明文档 `calculator.md`。\n\n**任务执行结果与分析：**\n\n遗憾的是，本次任务未能成功完成。系统反馈显示“超过最大尝试次数，编程失败”，这表明生成的文档未能通过完整性或质量检查。\n\n经过分析，我发现本次尝试生成的 `calculator.md` 内容仍然不完整，尤其是在**代码示例**部分。文档中缺少了关键的导入模块代码块、各个运算函数的具体调用示例代码，以及 `if __name__ == '__main__':` 块的完整代码和其对应的输出示例。这导致文档的实用性不足，未能达到生成高质量使用说明文档的期望。\n\n**当前系统状态：**\n\n*   `calculator.py` 的核心运算逻辑已实现，并且大部分功能通过了单元测试的初步验证。\n*   然而，单元测试中 `test_divide_by_zero_error` 用例仍因测试代码自身错误（`assertRaisesRegex` 参数使用不当）而失败，导致整个测试套件报告失败。\n*   `calculator.md` 文档生成失败且内容不完整。\n\n**下一步行动方向：**\n\n为了确保项目的完整性和质量，我们将严格按照以下步骤继续：\n\n1.  **修正单元测试：** 首要任务是修正 `test_divide_by_zero_error` 测试用例中 `assertRaisesRegex` 的用法，然后重新运行所有单元测试，以确保 `calculator.py` 的所有功能（特别是除零错误处理）都得到正确验证。\n2.  **完善使用说明文档：** 在确认 `calculator.py` 功能完全正确并通过所有测试后，我将重新编写并生成 `calculator.md` 文件，确保其中包含完整的代码示例、使用方法和错误处理说明，使其成为一份高质量且实用的使用说明文档。\n\n感谢您的指令！ | 输出: 超过最大尝试次数，编程失败。",
      "[执行成功] 执行结果: 您好！\n\n根据您的指令，我已成功为 `calculator.py` 中的所有运算函数编写并执行了全面的单元测试。\n\n**任务执行结果与分析：**\n\n我已成功修正了之前 `test_divide_by_zero_error` 测试用例中 `assertRaisesRegex` 参数使用不当的问题。重新运行所有单元测试后，所有测试用例均已**通过**，包括对除零错误处理的验证。这表明 `calculator.py` 的核心运算逻辑已得到全面验证，功能正确性得到确认。\n\n**单元测试报告摘要：**\n\n*   **测试文件：** `calculator.py`\n*   **测试套件：** `TestCalculator`\n*   **测试用例数量：** 9 个\n*   **通过数量：** 9 个\n*   **失败数量：** 0 个\n*   **错误数量：** 0 个\n*   **总耗时：** 0.001s\n*   **结果：** 所有测试均已通过。\n\n**当前系统状态：**\n\n*   `calculator.py` 的核心逻辑已实现，并通过了所有单元测试的验证，功能已完全正确。\n*   `test_divide_by_zero_error` 单元测试已成功修正并通过。\n*   `calculator.md` 使用说明文档的生成任务仍待完成，目前内容不完整。\n\n**下一步行动方向：**\n\n鉴于 `calculator.py` 的功能已通过单元测试的全面验证，下一步我们将专注于完善 `calculator.md` 使用说明文档。我将重新生成并完善该文档，确保其中包含完整的代码示例、使用方法和错误处理说明，以达到高质量文档的要求。\n\n感谢您的指令！ | 输出: 已重新加载 calculator 模块。\n开始运行单元测试...\n\n--- 单元测试报告 ---\ntest_add_boundary (__main__.TestCalculator)\n测试加法边界情况。 ... 加法边界情况测试通过。\nok\ntest_add_normal (__main__.TestCalculator)\n测试加法正常情况。 ... 加法正常情况测试通过。\nok\ntest_divide_boundary (__main__.TestCalculator)\n测试除法边界情况。 ... 除法边界情况测试通过。\nok\ntest_divide_by_zero_error (__main__.TestCalculator)\n测试除法除零错误处理。 ... 除法除零错误处理测试通过。\nok\ntest_divide_normal (__main__.TestCalculator)\n测试除法正常情况。 ... 除法正常情况测试通过。\nok\ntest_multiply_boundary (__main__.TestCalculator)\n测试乘法边界情况。 ... 乘法边界情况测试通过。\nok\ntest_multiply_normal (__main__.TestCalculator)\n测试乘法正常情况。 ... 乘法正常情况测试通过。\nok\ntest_subtract_boundary (__main__.TestCalculator)\n测试减法边界情况。 ... 减法边界情况测试通过。\nok\ntest_subtract_normal (__main__.TestCalculator)\n测试减法正常情况。 ... 减法正常情况测试通过。\nok\n\n----------------------------------------------------------------------\nRan 9 tests in 0.001s\n\nOK\n\n--- 单元测试报告结束 ---\n\n所有单元测试均已通过。任务完成。\n"
    ],
    "execution_config": {
      "timeout": 60,
      "retry_attempts": 3,
      "timestamp": "2025-06-25T17:03:54.937515"
    }
  },
  "failure_reason": null,
  "confidence_score": 0.0
}