{
  "id": "rule_671198_exec_20250628_061752",
  "rule_id": "rule_671198",
  "status": "completed",
  "result": {
    "success": true,
    "message": "执行结果: 好的，任务已成功执行。\n\n我已执行 `calculator.py` 文件，运行了其中包含的全部单元测试。测试结果确认，所有测试用例均已成功通过。\n\n**执行详情：**\n\n1.  **执行命令**: 我通过 `python calculator.py` 命令运行了脚本，这触发了文件末尾的 `if __name__ == '__main__':` 代码块，从而启动了 `unittest` 测试框架。\n2.  **结果验证**: 我捕获了测试运行的输出。标准错误流（`stderr`）中的结果明确显示所有测试均成功。\n\n**测试输出摘要：**\n\n```\n....\n----------------------------------------------------------------------\nRan 4 tests in 0.000s\n\nOK\n```\n\n输出中的 `OK` 状态和 `Ran 4 tests` 表明，针对加、减、乘、除四个函数的测试已全部顺利完成，并且所有断言均符合预期。\n\n至此，我们已成功完成您的所有目标：\n1.  ✅ 实现加减乘除四个基本运算\n2.  ✅ 编写完整的单元测试\n3.  ✅ **运行测试，确保测试通过**\n4.  ✅ 文件保存在 `calculator.py`\n\n项目已圆满完成。 | 输出: Executing tests in calculator.py...\n--- Captured STDOUT from test execution ---\nTesting add function...\nadd function tests passed.\nTesting divide function...\ndivide function tests passed.\nTesting multiply function...\nmultiply function tests passed.\nTesting subtract function...\nsubtract function tests passed.\n\n--- End of STDOUT ---\n\n--- Captured STDERR from test execution (Test Results) ---\n....\n----------------------------------------------------------------------\nRan 4 tests in 0.000s\n\nOK\n\n--- End of STDERR ---\n\nAll 4 unit tests passed successfully.\n任务完成\n",
    "data": {
      "code": "\ntry:\n    import runpy\n    import io\n    import contextlib\n    import os\n\n    file_path = 'calculator.py'\n    print(f\"Executing tests in {file_path}...\")\n\n    # Verify the file exists before trying to run it\n    assert os.path.exists(file_path), f\"File '{file_path}' not found.\"\n\n    # The previous step already added the main execution block.\n    # Now, we just need to execute the file.\n    # We will capture stdout and stderr to verify the test results.\n    stdout_capture = io.StringIO()\n    stderr_capture = io.StringIO()\n\n    # The unittest output goes to stderr by default.\n    # The print statements inside the tests go to stdout.\n    with contextlib.redirect_stdout(stdout_capture):\n        with contextlib.redirect_stderr(stderr_capture):\n            # Using runpy to execute the script is a clean way to run it.\n            # Setting run_name to '__main__' ensures the if __name__ == '__main__': block is executed.\n            runpy.run_path(file_path, run_name='__main__')\n\n    stdout_output = stdout_capture.getvalue()\n    stderr_output = stderr_capture.getvalue()\n\n    print(\"--- Captured STDOUT from test execution ---\")\n    print(stdout_output)\n    print(\"--- End of STDOUT ---\")\n\n    print(\"\\n--- Captured STDERR from test execution (Test Results) ---\")\n    print(stderr_output)\n    print(\"--- End of STDERR ---\")\n\n    # Verification\n    # A successful unittest run prints \"OK\" to stderr.\n    # It also mentions the number of tests run.\n    assert \"Ran 4 tests\" in stderr_output, \"Verification Failed: Did not run all 4 tests.\"\n    assert \"OK\" in stderr_output, \"Verification Failed: Tests did not pass successfully.\"\n    \n    print(\"\\nAll 4 unit tests passed successfully.\")\n    print(\"任务完成\")\n\nexcept AssertionError as e:\n    print(f\"发生错误: {str(e)}\")\nexcept FileNotFoundError as e:\n    print(f\"发生错误: {str(e)}\")\nexcept Exception as e:\n    print(f\"An unexpected error occurred: {str(e)}\")",
      "return_value": "好的，任务已成功执行。\n\n我已执行 `calculator.py` 文件，运行了其中包含的全部单元测试。测试结果确认，所有测试用例均已成功通过。\n\n**执行详情：**\n\n1.  **执行命令**: 我通过 `python calculator.py` 命令运行了脚本，这触发了文件末尾的 `if __name__ == '__main__':` 代码块，从而启动了 `unittest` 测试框架。\n2.  **结果验证**: 我捕获了测试运行的输出。标准错误流（`stderr`）中的结果明确显示所有测试均成功。\n\n**测试输出摘要：**\n\n```\n....\n----------------------------------------------------------------------\nRan 4 tests in 0.000s\n\nOK\n```\n\n输出中的 `OK` 状态和 `Ran 4 tests` 表明，针对加、减、乘、除四个函数的测试已全部顺利完成，并且所有断言均符合预期。\n\n至此，我们已成功完成您的所有目标：\n1.  ✅ 实现加减乘除四个基本运算\n2.  ✅ 编写完整的单元测试\n3.  ✅ **运行测试，确保测试通过**\n4.  ✅ 文件保存在 `calculator.py`\n\n项目已圆满完成。",
      "stdout": "Executing tests in calculator.py...\n--- Captured STDOUT from test execution ---\nTesting add function...\nadd function tests passed.\nTesting divide function...\ndivide function tests passed.\nTesting multiply function...\nmultiply function tests passed.\nTesting subtract function...\nsubtract function tests passed.\n\n--- End of STDOUT ---\n\n--- Captured STDERR from test execution (Test Results) ---\n....\n----------------------------------------------------------------------\nRan 4 tests in 0.000s\n\nOK\n\n--- End of STDERR ---\n\nAll 4 unit tests passed successfully.\n任务完成\n",
      "stderr": null
    },
    "error_details": null,
    "metadata": {
      "instruction": "\n执行任务: 在 `calculator.py` 文件末尾添加 `if __name__ == '__main__': unittest.main()` 代码块，然后执行该文件以运行所有单元测试。确认所有测试都通过。\n\n当前状态: 好的，这是根据您提供的信息生成的新系统状态描述：\n\n---\n\n### **系统状态描述**\n\n**状态：** 单元测试已编写完成，等待执行测试\n\n**1. 执行总结**\n*   **操作**: 执行了 `Write_Unit_Tests` 规则。\n*   **结果**: 成功。\n*   **产出**: 成功将 `unittest` 测试框架代码追加到 `calculator.py` 文件中。该文件现在同时包含核心功能函数和完整的单元测试类 (`TestCalculator`)。\n\n**2. 当前状态分析**\n*   **系统状态**: 项目代码和单元测试均已编写完成并保存在同一文件中。系统已准备好进入最终的验证阶段。\n*   **目标进度**: 整体目标的第1步（实现基本运算）、第2步（编写单元测试）和第4步（文件保存）均已完成。\n*   **下一步方向**: 根据项目目标，下一步是“运行测试，确保测试通过”。这与 `Run_Tests_And_Finalize` 规则的触发条件（代码和单元测试都已编写完成）完全匹配。\n\n**3. 规则执行关键数据**\n*   **`code_implemented`**: `True`\n*   **`source_code_file`**: `calculator.py`\n*   **`tests_exist`**: `True`\n*   **`tests_passed`**: `False`\n*   **`test_runner_command`**: `python calculator.py`\n\n规则上下文:\n- 规则名称: Run_Tests_And_Finalize\n- 期望结果: 终端输出显示所有测试均已成功通过，并且 `calculator.py` 文件是完整的、可独立运行测试的最终版本。\n- 执行阶段: verification\n\n相关上下文变量:\n- goal: \n    开发一个简单的计算器程序，要求：\n    1. 实现加减乘除四个基本运算\n    2. 编写完整的单元测试\n    3. 运行测试，确保测试通过\n    4. 文件保存在calculator.py\n    \n- last_execution_success: True\n\n最近执行历史:\n1. [iter_0] 工作流启动\n2. [执行成功] 执行结果: 好的，任务已成功执行。\n\n我已为您创建了 `calculator.py` 文件，并实现了加、减、乘、除四个基本运算函数：\n\n*   `add(a, b)`\n*   `subtract(a, b)`\n*   `multiply(a, b)`\n*   `divide(a, b)`\n\n根据您的要求，`divide` 函数已添加了对除数为零的检查，当除数为零时会引发 `ValueError`。\n\n计算器的基础功能已准备就绪，我们可以继续下一步操作了。 | 输出: calculator.py file created successfully.\n任务完成\n\n3. [执行成功] 执行结果: 好的，任务已成功执行。\n\n我已按照您的要求，使用 `unittest` 框架为 `calculator.py` 文件中的所有函数编写了全面的单元测试。\n\n**执行详情：**\n\n1.  **创建测试类**: 我在 `calculator.py` 文件中追加了一个名为 `TestCalculator` 的测试类，该类继承自 `unittest.TestCase`。\n2.  **编写测试用例**: 在 `TestCalculator` 类中，我为 `add`、`subtract`、`multiply` 和 `divide` 函数分别创建了测试方法。\n3.  **覆盖全面场景**:\n    *   **正常情况**: 测试了基本的正数运算。\n    *   **边界情况**: 包含了对负数和零的运算测试。\n    *   **异常情况**: 专门为 `divide` 函数设计了测试，使用 `assertRaises` 来验证当除数为零时，是否能正确抛出 `ValueError` 异常。\n\n`calculator.py` 文件现在已包含完整的计算器功能及其对应的单元测试代码。\n\n接下来，我们可以运行这些测试来验证所有功能的正确性。 | 输出: Appending unit tests to calculator.py...\nSuccessfully appended tests to calculator.py.\nVerifying file content...\nVerification successful. calculator.py now contains the unit tests.\n\n--- Final content of calculator.py ---\n\ndef add(a, b):\n    \"\"\"Return the sum of a and b.\"\"\"\n    return a + b\n\ndef subtract(a, b):\n    \"\"\"Return the difference of a and b.\"\"\"\n    return a - b\n\ndef multiply(a, b):\n    \"\"\"Return the product of a and b.\"\"\"\n    return a * b\n\ndef divide(a, b):\n    \"\"\"Return the division of a by b.\"\"\"\n    if b == 0:\n        raise ValueError(\"Cannot divide by zero\")\n    return a / b\n\n\n# --- Unit Tests ---\nimport unittest\n\nclass TestCalculator(unittest.TestCase):\n    \"\"\"Unit tests for the calculator functions.\"\"\"\n\n    def test_add(self):\n        \"\"\"Test the add function with various cases.\"\"\"\n        print(\"Testing add function...\")\n        self.assertEqual(add(1, 2), 3, \"Test Case Failed: 1 + 2\")\n        self.assertEqual(add(-1, 1), 0, \"Test Case Failed: -1 + 1\")\n        self.assertEqual(add(-1, -1), -2, \"Test Case Failed: -1 + -1\")\n        self.assertEqual(add(0, 0), 0, \"Test Case Failed: 0 + 0\")\n        print(\"add function tests passed.\")\n\n    def test_subtract(self):\n        \"\"\"Test the subtract function with various cases.\"\"\"\n        print(\"Testing subtract function...\")\n        self.assertEqual(subtract(10, 5), 5, \"Test Case Failed: 10 - 5\")\n        self.assertEqual(subtract(-1, 1), -2, \"Test Case Failed: -1 - 1\")\n        self.assertEqual(subtract(-1, -1), 0, \"Test Case Failed: -1 - -1\")\n        self.assertEqual(subtract(5, 10), -5, \"Test Case Failed: 5 - 10\")\n        self.assertEqual(subtract(0, 0), 0, \"Test Case Failed: 0 - 0\")\n        print(\"subtract function tests passed.\")\n\n    def test_multiply(self):\n        \"\"\"Test the multiply function with various cases.\"\"\"\n        print(\"Testing multiply function...\")\n        self.assertEqual(multiply(3, 4), 12, \"Test Case Failed: 3 * 4\")\n        self.assertEqual(multiply(-1, 3), -3, \"Test Case Failed: -1 * 3\")\n        self.assertEqual(multiply(-1, -1), 1, \"Test Case Failed: -1 * -1\")\n        self.assertEqual(multiply(10, 0), 0, \"Test Case Failed: 10 * 0\")\n        self.assertEqual(multiply(0, 10), 0, \"Test Case Failed: 0 * 10\")\n        print(\"multiply function tests passed.\")\n\n    def test_divide(self):\n        \"\"\"Test the divide function, including division by zero.\"\"\"\n        print(\"Testing divide function...\")\n        self.assertEqual(divide(10, 2), 5, \"Test Case Failed: 10 / 2\")\n        self.assertEqual(divide(-10, 2), -5, \"Test Case Failed: -10 / 2\")\n        self.assertEqual(divide(5, 2), 2.5, \"Test Case Failed: 5 / 2\")\n        \n        # Test for division by zero exception\n        with self.assertRaises(ValueError):\n            divide(10, 0)\n        print(\"divide function tests passed.\")\n\nif __name__ == '__main__':\n    # Note: The output of unittest.main() goes to stderr by default.\n    unittest.main(exit=False)\n\n--- End of content ---\n任务完成\n\n\n请根据以上信息执行任务: 在 `calculator.py` 文件末尾添加 `if __name__ == '__main__': unittest.main()` 代码块，然后执行该文件以运行所有单元测试。确认所有测试都通过。",
      "source_type": "agent_base_result",
      "has_code": true,
      "has_output": true
    }
  },
  "completed_at": "2025-06-28T06:18:58.072665",
  "execution_context": {
    "rule_info": {
      "id": "rule_671198",
      "name": "Run_Tests_And_Finalize",
      "condition": "如果代码和单元测试都已编写完成",
      "action": "在 `calculator.py` 文件末尾添加 `if __name__ == '__main__': unittest.main()` 代码块，然后执行该文件以运行所有单元测试。确认所有测试都通过。",
      "expected_outcome": "终端输出显示所有测试均已成功通过，并且 `calculator.py` 文件是完整的、可独立运行测试的最终版本。",
      "priority": 80,
      "phase": "verification"
    },
    "state_info": {
      "description": "好的，这是根据您提供的信息生成的新系统状态描述：\n\n---\n\n### **系统状态描述**\n\n**状态：** 单元测试已编写完成，等待执行测试\n\n**1. 执行总结**\n*   **操作**: 执行了 `Write_Unit_Tests` 规则。\n*   **结果**: 成功。\n*   **产出**: 成功将 `unittest` 测试框架代码追加到 `calculator.py` 文件中。该文件现在同时包含核心功能函数和完整的单元测试类 (`TestCalculator`)。\n\n**2. 当前状态分析**\n*   **系统状态**: 项目代码和单元测试均已编写完成并保存在同一文件中。系统已准备好进入最终的验证阶段。\n*   **目标进度**: 整体目标的第1步（实现基本运算）、第2步（编写单元测试）和第4步（文件保存）均已完成。\n*   **下一步方向**: 根据项目目标，下一步是“运行测试，确保测试通过”。这与 `Run_Tests_And_Finalize` 规则的触发条件（代码和单元测试都已编写完成）完全匹配。\n\n**3. 规则执行关键数据**\n*   **`code_implemented`**: `True`\n*   **`source_code_file`**: `calculator.py`\n*   **`tests_exist`**: `True`\n*   **`tests_passed`**: `False`\n*   **`test_runner_command`**: `python calculator.py`",
      "iteration_count": 2,
      "workflow_id": "workflow_\n____开发一个简单的计算器程序，要求_20250628_0613",
      "goal_achieved": false
    },
    "context_variables": {
      "goal": "\n    开发一个简单的计算器程序，要求：\n    1. 实现加减乘除四个基本运算\n    2. 编写完整的单元测试\n    3. 运行测试，确保测试通过\n    4. 文件保存在calculator.py\n    ",
      "last_execution_success": true
    },
    "recent_history": [
      "[iter_0] 工作流启动",
      "[执行成功] 执行结果: 好的，任务已成功执行。\n\n我已为您创建了 `calculator.py` 文件，并实现了加、减、乘、除四个基本运算函数：\n\n*   `add(a, b)`\n*   `subtract(a, b)`\n*   `multiply(a, b)`\n*   `divide(a, b)`\n\n根据您的要求，`divide` 函数已添加了对除数为零的检查，当除数为零时会引发 `ValueError`。\n\n计算器的基础功能已准备就绪，我们可以继续下一步操作了。 | 输出: calculator.py file created successfully.\n任务完成\n",
      "[执行成功] 执行结果: 好的，任务已成功执行。\n\n我已按照您的要求，使用 `unittest` 框架为 `calculator.py` 文件中的所有函数编写了全面的单元测试。\n\n**执行详情：**\n\n1.  **创建测试类**: 我在 `calculator.py` 文件中追加了一个名为 `TestCalculator` 的测试类，该类继承自 `unittest.TestCase`。\n2.  **编写测试用例**: 在 `TestCalculator` 类中，我为 `add`、`subtract`、`multiply` 和 `divide` 函数分别创建了测试方法。\n3.  **覆盖全面场景**:\n    *   **正常情况**: 测试了基本的正数运算。\n    *   **边界情况**: 包含了对负数和零的运算测试。\n    *   **异常情况**: 专门为 `divide` 函数设计了测试，使用 `assertRaises` 来验证当除数为零时，是否能正确抛出 `ValueError` 异常。\n\n`calculator.py` 文件现在已包含完整的计算器功能及其对应的单元测试代码。\n\n接下来，我们可以运行这些测试来验证所有功能的正确性。 | 输出: Appending unit tests to calculator.py...\nSuccessfully appended tests to calculator.py.\nVerifying file content...\nVerification successful. calculator.py now contains the unit tests.\n\n--- Final content of calculator.py ---\n\ndef add(a, b):\n    \"\"\"Return the sum of a and b.\"\"\"\n    return a + b\n\ndef subtract(a, b):\n    \"\"\"Return the difference of a and b.\"\"\"\n    return a - b\n\ndef multiply(a, b):\n    \"\"\"Return the product of a and b.\"\"\"\n    return a * b\n\ndef divide(a, b):\n    \"\"\"Return the division of a by b.\"\"\"\n    if b == 0:\n        raise ValueError(\"Cannot divide by zero\")\n    return a / b\n\n\n# --- Unit Tests ---\nimport unittest\n\nclass TestCalculator(unittest.TestCase):\n    \"\"\"Unit tests for the calculator functions.\"\"\"\n\n    def test_add(self):\n        \"\"\"Test the add function with various cases.\"\"\"\n        print(\"Testing add function...\")\n        self.assertEqual(add(1, 2), 3, \"Test Case Failed: 1 + 2\")\n        self.assertEqual(add(-1, 1), 0, \"Test Case Failed: -1 + 1\")\n        self.assertEqual(add(-1, -1), -2, \"Test Case Failed: -1 + -1\")\n        self.assertEqual(add(0, 0), 0, \"Test Case Failed: 0 + 0\")\n        print(\"add function tests passed.\")\n\n    def test_subtract(self):\n        \"\"\"Test the subtract function with various cases.\"\"\"\n        print(\"Testing subtract function...\")\n        self.assertEqual(subtract(10, 5), 5, \"Test Case Failed: 10 - 5\")\n        self.assertEqual(subtract(-1, 1), -2, \"Test Case Failed: -1 - 1\")\n        self.assertEqual(subtract(-1, -1), 0, \"Test Case Failed: -1 - -1\")\n        self.assertEqual(subtract(5, 10), -5, \"Test Case Failed: 5 - 10\")\n        self.assertEqual(subtract(0, 0), 0, \"Test Case Failed: 0 - 0\")\n        print(\"subtract function tests passed.\")\n\n    def test_multiply(self):\n        \"\"\"Test the multiply function with various cases.\"\"\"\n        print(\"Testing multiply function...\")\n        self.assertEqual(multiply(3, 4), 12, \"Test Case Failed: 3 * 4\")\n        self.assertEqual(multiply(-1, 3), -3, \"Test Case Failed: -1 * 3\")\n        self.assertEqual(multiply(-1, -1), 1, \"Test Case Failed: -1 * -1\")\n        self.assertEqual(multiply(10, 0), 0, \"Test Case Failed: 10 * 0\")\n        self.assertEqual(multiply(0, 10), 0, \"Test Case Failed: 0 * 10\")\n        print(\"multiply function tests passed.\")\n\n    def test_divide(self):\n        \"\"\"Test the divide function, including division by zero.\"\"\"\n        print(\"Testing divide function...\")\n        self.assertEqual(divide(10, 2), 5, \"Test Case Failed: 10 / 2\")\n        self.assertEqual(divide(-10, 2), -5, \"Test Case Failed: -10 / 2\")\n        self.assertEqual(divide(5, 2), 2.5, \"Test Case Failed: 5 / 2\")\n        \n        # Test for division by zero exception\n        with self.assertRaises(ValueError):\n            divide(10, 0)\n        print(\"divide function tests passed.\")\n\nif __name__ == '__main__':\n    # Note: The output of unittest.main() goes to stderr by default.\n    unittest.main(exit=False)\n\n--- End of content ---\n任务完成\n"
    ],
    "execution_config": {
      "timeout": 60,
      "retry_attempts": 3,
      "timestamp": "2025-06-28T06:17:52.712588"
    }
  },
  "failure_reason": null,
  "confidence_score": 1.0
}