{
  "id": "rule_765129_exec_20250628_021930",
  "rule_id": "rule_765129",
  "status": "completed",
  "result": {
    "success": true,
    "message": "执行结果: 好的，任务已成功执行。\n\n遵照您的指令，我已执行了 `calculator.py` 文件中包含的 `unittest` 测试套件，并对结果进行了验证。\n\n测试结果表明，所有测试用例均已成功通过。这确认了我们编写的加、减、乘、除四个函数（包括对除零异常的处理）均按预期正确工作。\n\n以下是 `unittest` 框架输出的测试摘要：\n\n```\ntest_add (__main__.TestCalculator) ... ok\ntest_divide (__main__.TestCalculator) ... ok\ntest_multiply (__main__.TestCalculator) ... ok\ntest_subtract (__main__.TestCalculator) ... ok\n\n----------------------------------------------------------------------\nRan 4 tests in 0.001s\n\nOK\n```\n\n至此，我们已经完成了您总体目标中的第三项要求：“运行测试，确保测试通过”。\n\n接下来，我们可以着手完成最后一项任务：生成程序的 Markdown 使用说明文档。 | 输出: Attempting to run unit tests in 'calculator.py'...\n--- Captured STDOUT from test execution ---\nTesting add function...\nTesting divide function...\nTesting division by zero...\nTesting multiply function...\nTesting subtract function...\n\n-----------------------------------------\n--- Captured STDERR from test execution ---\ntest_add (__main__.TestCalculator)\nTest case for the add function. ... ok\ntest_divide (__main__.TestCalculator)\nTest case for the divide function. ... ok\ntest_multiply (__main__.TestCalculator)\nTest case for the multiply function. ... ok\ntest_subtract (__main__.TestCalculator)\nTest case for the subtract function. ... ok\n\n----------------------------------------------------------------------\nRan 4 tests in 0.001s\n\nOK\n\n-----------------------------------------\nVerifying test results...\nAll 4 unit tests passed successfully.\n任务完成\n",
    "data": {
      "code": "\ntry:\n    import runpy\n    import sys\n    import io\n    import os\n\n    file_path = 'calculator.py'\n    print(f\"Attempting to run unit tests in '{file_path}'...\")\n\n    # --- Pre-execution Check ---\n    if not os.path.exists(file_path):\n        raise FileNotFoundError(f\"The file '{file_path}' does not exist. Cannot run tests.\")\n\n    # --- Execution with Output Capture ---\n    # unittest prints its summary to stderr by default, while our print statements go to stdout.\n    # We capture both to get a complete picture.\n    original_stdout = sys.stdout\n    original_stderr = sys.stderr\n    captured_stdout = io.StringIO()\n    captured_stderr = io.StringIO()\n    \n    test_result_summary = \"\"\n    test_run_successful = False\n\n    try:\n        sys.stdout = captured_stdout\n        sys.stderr = captured_stderr\n        \n        # Using runpy.run_path to execute the file.\n        # Setting run_name to '__main__' is crucial to trigger the test runner block.\n        runpy.run_path(file_path, run_name='__main__')\n        \n    finally:\n        # Ensure that we always restore the original stdout/stderr\n        sys.stdout = original_stdout\n        sys.stderr = original_stderr\n\n    # Retrieve the captured output\n    stdout_output = captured_stdout.getvalue()\n    stderr_output = captured_stderr.getvalue()\n    \n    # Print the captured output for logging and diagnosis\n    print(\"--- Captured STDOUT from test execution ---\")\n    print(stdout_output)\n    print(\"-----------------------------------------\")\n    print(\"--- Captured STDERR from test execution ---\")\n    print(stderr_output)\n    print(\"-----------------------------------------\")\n\n    # --- Verification ---\n    print(\"Verifying test results...\")\n    \n    # A successful run with verbosity=2 will print \"Ran X tests\" and \"OK\" to stderr.\n    # We check for these indicators.\n    assert \"Ran 4 tests\" in stderr_output, \"Verification failed: Expected to run 4 tests.\"\n    assert \"OK\" in stderr_output, \"Verification failed: The 'OK' status was not found in the test summary.\"\n    assert \"FAILED\" not in stderr_output, \"Verification failed: Tests failed.\"\n    assert \"ERROR\" not in stderr_output, \"Verification failed: Tests encountered errors.\"\n\n    print(\"All 4 unit tests passed successfully.\")\n    print(\"任务完成\")\n\nexcept FileNotFoundError as e:\n    print(f\"发生错误: {str(e)}\")\nexcept AssertionError as e:\n    print(f\"发生错误: {str(e)}\")\nexcept Exception as e:\n    print(f\"发生错误: An unexpected error occurred during test execution: {str(e)}\")",
      "return_value": "好的，任务已成功执行。\n\n遵照您的指令，我已执行了 `calculator.py` 文件中包含的 `unittest` 测试套件，并对结果进行了验证。\n\n测试结果表明，所有测试用例均已成功通过。这确认了我们编写的加、减、乘、除四个函数（包括对除零异常的处理）均按预期正确工作。\n\n以下是 `unittest` 框架输出的测试摘要：\n\n```\ntest_add (__main__.TestCalculator) ... ok\ntest_divide (__main__.TestCalculator) ... ok\ntest_multiply (__main__.TestCalculator) ... ok\ntest_subtract (__main__.TestCalculator) ... ok\n\n----------------------------------------------------------------------\nRan 4 tests in 0.001s\n\nOK\n```\n\n至此，我们已经完成了您总体目标中的第三项要求：“运行测试，确保测试通过”。\n\n接下来，我们可以着手完成最后一项任务：生成程序的 Markdown 使用说明文档。",
      "stdout": "Attempting to run unit tests in 'calculator.py'...\n--- Captured STDOUT from test execution ---\nTesting add function...\nTesting divide function...\nTesting division by zero...\nTesting multiply function...\nTesting subtract function...\n\n-----------------------------------------\n--- Captured STDERR from test execution ---\ntest_add (__main__.TestCalculator)\nTest case for the add function. ... ok\ntest_divide (__main__.TestCalculator)\nTest case for the divide function. ... ok\ntest_multiply (__main__.TestCalculator)\nTest case for the multiply function. ... ok\ntest_subtract (__main__.TestCalculator)\nTest case for the subtract function. ... ok\n\n----------------------------------------------------------------------\nRan 4 tests in 0.001s\n\nOK\n\n-----------------------------------------\nVerifying test results...\nAll 4 unit tests passed successfully.\n任务完成\n",
      "stderr": null
    },
    "error_details": null,
    "metadata": {
      "instruction": "\n执行任务: 执行 `calculator.py` 文件中的 `unittest` 测试套件，并捕获测试结果。确保所有测试用例都成功通过。\n\n当前状态: 好的，这是基于您提供信息生成的新系统状态描述。\n\n---\n\n### 新的系统状态描述\n\n**1. 执行总结**\n- **操作**: 执行了“编写单元测试用例”的规则。\n- **结果**: 操作成功。系统已将使用 `unittest` 框架编写的单元测试用例追加到 `calculator.py` 文件中。测试用例覆盖了正常、边界和异常（除零）情况。文件更新已通过验证。\n\n**2. 当前系统状态**\n- **目标进度**: 整体目标“开发一个简单的计算器程序”已完成第二步。具体来说，要求2（编写完整的单元测试）已经达成。\n- **产出物**: `calculator.py` 文件已被更新，现在同时包含核心运算函数和对应的单元测试代码。\n- **系统状态**: 已从“核心功能已实现”进入“单元测试已编写”状态。\n\n**3. 下一步行动方向**\n- **触发条件**: 当前状态（`calculator.py` 文件中已包含单元测试代码）满足了规则【执行测试并验证代码】的执行条件。\n- **推荐行动**: 下一步应是执行 `calculator.py` 文件中的单元测试，并验证所有测试用例是否通过。\n\n**4. 规则集关键数据和状态信息**\n- **状态变化**: `calculator.py` 文件内容已更新，现包含可执行的测试套件。\n- **关键数据**:\n    - **文件名**: `calculator.py`\n    - **文件内容特征**: 文件中存在 `import unittest`，`class TestCalculator(unittest.TestCase)` 以及 `if __name__ == '__main__':` 执行块。这些是执行测试的关键标识。\n    - **已完成任务**: 实现基本运算（要求1），编写单元测试（要求2），文件保存在calculator.py（要求5）。\n    - **待办任务**: 运行测试（要求3），生成文档（要求4）。\n\n规则上下文:\n- 规则名称: 执行测试并验证代码\n- 期望结果: 返回测试执行结果，明确指出所有测试均已通过。\n- 执行阶段: verification\n\n相关上下文变量:\n- goal: \n    开发一个简单的计算器程序，要求：\n    1. 实现加减乘除四个基本运算\n    2. 编写完整的单元测试\n    3. 运行测试，确保测试通过\n    4. 生成使用说明文档，使用markdown格式，文件保存在calculator.md\n    5. 文件保存在calculator.py\n    \n- last_execution_success: True\n\n最近执行历史:\n1. [iter_0] 工作流启动\n2. [执行成功] 执行结果: 好的，任务已成功执行。\n\n我已经按照您的指令，创建了 `calculator.py` 文件。该文件中包含了 `add`, `subtract`, `multiply`, 和 `divide` 四个函数，分别用于实现加、减、乘、除运算。其中，`divide` 函数已按要求处理了除数为零的异常情况。\n\n以下是 `calculator.py` 文件的内容：\n\n```python\n# calculator.py\n\ndef add(a, b):\n    '''This function adds two numbers'''\n    return a + b\n\ndef subtract(a, b):\n    '''This function subtracts two numbers'''\n    return a - b\n\ndef multiply(a, b):\n    '''This function multiplies two numbers'''\n    return a * b\n\ndef divide(a, b):\n    '''This function divides two numbers'''\n    if b == 0:\n        raise ValueError(\"Cannot divide by zero!\")\n    return a / b\n```\n\n我们已经完成了计算器核心功能的实现。接下来，我将继续执行工作流中的下一步。 | 输出: 正在创建并写入文件: calculator.py\n文件 calculator.py 已成功写入。\n开始验证任务...\n验证通过: 文件 calculator.py 已存在。\n验证通过: 文件内容正确。\n任务完成\n\n3. [执行成功] 执行结果: 好的，任务已成功执行。\n\n遵照您的指令，我已使用 Python 的 `unittest` 框架，为 `calculator.py` 文件中的四个核心运算函数编写了全面的单元测试，并将这些测试代码追加到了原文件的末尾。\n\n这些测试用例覆盖了您要求的多种情况：\n*   **正常情况**：如 `10 + 5` 或 `10 / 2`。\n*   **边界情况**：包括对负数和零的运算。\n*   **异常情况**：特别针对除法函数，验证了当除数为零时，程序能够正确地抛出 `ValueError` 异常。\n\n以下是更新后 `calculator.py` 文件的完整内容，现在它同时包含了计算器函数和它们的单元测试：\n\n```python\n# calculator.py\n\ndef add(a, b):\n    '''This function adds two numbers'''\n    return a + b\n\ndef subtract(a, b):\n    '''This function subtracts two numbers'''\n    return a - b\n\ndef multiply(a, b):\n    '''This function multiplies two numbers'''\n    return a * b\n\ndef divide(a, b):\n    '''This function divides two numbers'''\n    if b == 0:\n        raise ValueError(\"Cannot divide by zero!\")\n    return a / b\n\n\nimport unittest\n\nclass TestCalculator(unittest.TestCase):\n    '''Unit tests for the calculator functions.'''\n\n    def test_add(self):\n        '''Test case for the add function.'''\n        print(\"Testing add function...\")\n        self.assertEqual(add(10, 5), 15)\n        self.assertEqual(add(-1, 1), 0)\n        self.assertEqual(add(-1, -1), -2)\n        self.assertEqual(add(0, 0), 0)\n        self.assertAlmostEqual(add(0.1, 0.2), 0.3)\n\n    def test_subtract(self):\n        '''Test case for the subtract function.'''\n        print(\"Testing subtract function...\")\n        self.assertEqual(subtract(10, 5), 5)\n        self.assertEqual(subtract(-1, 1), -2)\n        self.assertEqual(subtract(-1, -1), 0)\n        self.assertEqual(subtract(5, 10), -5)\n        self.assertEqual(subtract(0, 0), 0)\n\n    def test_multiply(self):\n        '''Test case for the multiply function.'''\n        print(\"Testing multiply function...\")\n        self.assertEqual(multiply(3, 4), 12)\n        self.assertEqual(multiply(-1, 1), -1)\n        self.assertEqual(multiply(-1, -1), 1)\n        self.assertEqual(multiply(10, 0), 0)\n        self.assertEqual(multiply(0, 10), 0)\n\n    def test_divide(self):\n        '''Test case for the divide function.'''\n        print(\"Testing divide function...\")\n        self.assertEqual(divide(10, 2), 5)\n        self.assertEqual(divide(-1, 1), -1)\n        self.assertEqual(divide(-1, -1), 1)\n        self.assertAlmostEqual(divide(5, 2), 2.5)\n        \n        # Test for division by zero exception\n        print(\"Testing division by zero...\")\n        with self.assertRaises(ValueError):\n            divide(10, 0)\n\n# This block allows running tests directly from the command line.\n# It is included here to prepare for the next step of the workflow.\nif __name__ == '__main__':\n    # Using verbosity=2 for more detailed test output.\n    # Using exit=False and argv to prevent issues in some environments like notebooks.\n    unittest.main(argv=['first-arg-is-ignored'], exit=False, verbosity=2)\n\n```\n\n我们已经成功地为核心功能编写了测试用例。根据您的目标，下一步是运行这些测试，以确保所有功能都按预期工作并且所有测试都能通过。 | 输出: Appending unit tests to calculator.py...\nSuccessfully appended unit tests to calculator.py.\nVerifying the file update...\nVerification successful. The file 'calculator.py' has been updated with unit tests.\n任务完成\n\n\n请根据以上信息执行任务: 执行 `calculator.py` 文件中的 `unittest` 测试套件，并捕获测试结果。确保所有测试用例都成功通过。",
      "source_type": "agent_base_result",
      "has_code": true,
      "has_output": true
    }
  },
  "completed_at": "2025-06-28T02:20:38.094228",
  "execution_context": {
    "rule_info": {
      "id": "rule_765129",
      "name": "执行测试并验证代码",
      "condition": "如果 `calculator.py` 文件中已包含单元测试代码",
      "action": "执行 `calculator.py` 文件中的 `unittest` 测试套件，并捕获测试结果。确保所有测试用例都成功通过。",
      "expected_outcome": "返回测试执行结果，明确指出所有测试均已通过。",
      "priority": 80,
      "phase": "verification"
    },
    "state_info": {
      "description": "好的，这是基于您提供信息生成的新系统状态描述。\n\n---\n\n### 新的系统状态描述\n\n**1. 执行总结**\n- **操作**: 执行了“编写单元测试用例”的规则。\n- **结果**: 操作成功。系统已将使用 `unittest` 框架编写的单元测试用例追加到 `calculator.py` 文件中。测试用例覆盖了正常、边界和异常（除零）情况。文件更新已通过验证。\n\n**2. 当前系统状态**\n- **目标进度**: 整体目标“开发一个简单的计算器程序”已完成第二步。具体来说，要求2（编写完整的单元测试）已经达成。\n- **产出物**: `calculator.py` 文件已被更新，现在同时包含核心运算函数和对应的单元测试代码。\n- **系统状态**: 已从“核心功能已实现”进入“单元测试已编写”状态。\n\n**3. 下一步行动方向**\n- **触发条件**: 当前状态（`calculator.py` 文件中已包含单元测试代码）满足了规则【执行测试并验证代码】的执行条件。\n- **推荐行动**: 下一步应是执行 `calculator.py` 文件中的单元测试，并验证所有测试用例是否通过。\n\n**4. 规则集关键数据和状态信息**\n- **状态变化**: `calculator.py` 文件内容已更新，现包含可执行的测试套件。\n- **关键数据**:\n    - **文件名**: `calculator.py`\n    - **文件内容特征**: 文件中存在 `import unittest`，`class TestCalculator(unittest.TestCase)` 以及 `if __name__ == '__main__':` 执行块。这些是执行测试的关键标识。\n    - **已完成任务**: 实现基本运算（要求1），编写单元测试（要求2），文件保存在calculator.py（要求5）。\n    - **待办任务**: 运行测试（要求3），生成文档（要求4）。",
      "iteration_count": 2,
      "workflow_id": "workflow_\n____开发一个简单的计算器程序，要求_20250628_0213",
      "goal_achieved": false
    },
    "context_variables": {
      "goal": "\n    开发一个简单的计算器程序，要求：\n    1. 实现加减乘除四个基本运算\n    2. 编写完整的单元测试\n    3. 运行测试，确保测试通过\n    4. 生成使用说明文档，使用markdown格式，文件保存在calculator.md\n    5. 文件保存在calculator.py\n    ",
      "last_execution_success": true
    },
    "recent_history": [
      "[iter_0] 工作流启动",
      "[执行成功] 执行结果: 好的，任务已成功执行。\n\n我已经按照您的指令，创建了 `calculator.py` 文件。该文件中包含了 `add`, `subtract`, `multiply`, 和 `divide` 四个函数，分别用于实现加、减、乘、除运算。其中，`divide` 函数已按要求处理了除数为零的异常情况。\n\n以下是 `calculator.py` 文件的内容：\n\n```python\n# calculator.py\n\ndef add(a, b):\n    '''This function adds two numbers'''\n    return a + b\n\ndef subtract(a, b):\n    '''This function subtracts two numbers'''\n    return a - b\n\ndef multiply(a, b):\n    '''This function multiplies two numbers'''\n    return a * b\n\ndef divide(a, b):\n    '''This function divides two numbers'''\n    if b == 0:\n        raise ValueError(\"Cannot divide by zero!\")\n    return a / b\n```\n\n我们已经完成了计算器核心功能的实现。接下来，我将继续执行工作流中的下一步。 | 输出: 正在创建并写入文件: calculator.py\n文件 calculator.py 已成功写入。\n开始验证任务...\n验证通过: 文件 calculator.py 已存在。\n验证通过: 文件内容正确。\n任务完成\n",
      "[执行成功] 执行结果: 好的，任务已成功执行。\n\n遵照您的指令，我已使用 Python 的 `unittest` 框架，为 `calculator.py` 文件中的四个核心运算函数编写了全面的单元测试，并将这些测试代码追加到了原文件的末尾。\n\n这些测试用例覆盖了您要求的多种情况：\n*   **正常情况**：如 `10 + 5` 或 `10 / 2`。\n*   **边界情况**：包括对负数和零的运算。\n*   **异常情况**：特别针对除法函数，验证了当除数为零时，程序能够正确地抛出 `ValueError` 异常。\n\n以下是更新后 `calculator.py` 文件的完整内容，现在它同时包含了计算器函数和它们的单元测试：\n\n```python\n# calculator.py\n\ndef add(a, b):\n    '''This function adds two numbers'''\n    return a + b\n\ndef subtract(a, b):\n    '''This function subtracts two numbers'''\n    return a - b\n\ndef multiply(a, b):\n    '''This function multiplies two numbers'''\n    return a * b\n\ndef divide(a, b):\n    '''This function divides two numbers'''\n    if b == 0:\n        raise ValueError(\"Cannot divide by zero!\")\n    return a / b\n\n\nimport unittest\n\nclass TestCalculator(unittest.TestCase):\n    '''Unit tests for the calculator functions.'''\n\n    def test_add(self):\n        '''Test case for the add function.'''\n        print(\"Testing add function...\")\n        self.assertEqual(add(10, 5), 15)\n        self.assertEqual(add(-1, 1), 0)\n        self.assertEqual(add(-1, -1), -2)\n        self.assertEqual(add(0, 0), 0)\n        self.assertAlmostEqual(add(0.1, 0.2), 0.3)\n\n    def test_subtract(self):\n        '''Test case for the subtract function.'''\n        print(\"Testing subtract function...\")\n        self.assertEqual(subtract(10, 5), 5)\n        self.assertEqual(subtract(-1, 1), -2)\n        self.assertEqual(subtract(-1, -1), 0)\n        self.assertEqual(subtract(5, 10), -5)\n        self.assertEqual(subtract(0, 0), 0)\n\n    def test_multiply(self):\n        '''Test case for the multiply function.'''\n        print(\"Testing multiply function...\")\n        self.assertEqual(multiply(3, 4), 12)\n        self.assertEqual(multiply(-1, 1), -1)\n        self.assertEqual(multiply(-1, -1), 1)\n        self.assertEqual(multiply(10, 0), 0)\n        self.assertEqual(multiply(0, 10), 0)\n\n    def test_divide(self):\n        '''Test case for the divide function.'''\n        print(\"Testing divide function...\")\n        self.assertEqual(divide(10, 2), 5)\n        self.assertEqual(divide(-1, 1), -1)\n        self.assertEqual(divide(-1, -1), 1)\n        self.assertAlmostEqual(divide(5, 2), 2.5)\n        \n        # Test for division by zero exception\n        print(\"Testing division by zero...\")\n        with self.assertRaises(ValueError):\n            divide(10, 0)\n\n# This block allows running tests directly from the command line.\n# It is included here to prepare for the next step of the workflow.\nif __name__ == '__main__':\n    # Using verbosity=2 for more detailed test output.\n    # Using exit=False and argv to prevent issues in some environments like notebooks.\n    unittest.main(argv=['first-arg-is-ignored'], exit=False, verbosity=2)\n\n```\n\n我们已经成功地为核心功能编写了测试用例。根据您的目标，下一步是运行这些测试，以确保所有功能都按预期工作并且所有测试都能通过。 | 输出: Appending unit tests to calculator.py...\nSuccessfully appended unit tests to calculator.py.\nVerifying the file update...\nVerification successful. The file 'calculator.py' has been updated with unit tests.\n任务完成\n"
    ],
    "execution_config": {
      "timeout": 60,
      "retry_attempts": 3,
      "timestamp": "2025-06-28T02:19:30.287034"
    }
  },
  "failure_reason": null,
  "confidence_score": 1.0
}